#VRML_SIM R2023b utf8

EXTERNPROTO "https://raw.githubusercontent.com/cyberbotics/webots/R2023b/projects/objects/backgrounds/protos/TexturedBackground.proto"
EXTERNPROTO "https://raw.githubusercontent.com/cyberbotics/webots/R2023b/projects/objects/backgrounds/protos/TexturedBackgroundLight.proto"
EXTERNPROTO "https://raw.githubusercontent.com/cyberbotics/webots/R2023b/projects/objects/floors/protos/Floor.proto"
EXTERNPROTO "https://raw.githubusercontent.com/cyberbotics/webots/R2023b/projects/robots/dji/mavic/protos/Mavic2Pro.proto"
EXTERNPROTO "https://raw.githubusercontent.com/cyberbotics/webots/R2023b/projects/appearances/protos/SandyGround.proto"

WorldInfo {
  basicTimeStep 16
  defaultDamping Damping {
    linear 0.5
    angular 0.3
  }
}
Viewpoint {
  orientation -0.14620295027651187 0.7904538756009932 0.5948170877486734 0.6029709521832103
  position -13.63382154042783 -5.95262036257594 9.693679414961107
  follow "Mavic 2 PRO"
  followType "None"
}
TexturedBackground {
}
TexturedBackgroundLight {
}
Floor {
  size 15 15
  appearance SandyGround {
  }
}
Robot {
  translation 4.641877145252289e-07 -3.489537444586903e-06 0.03990488411067251
  children [
    GPS {
      translation 0 0 0.005
      children [
        Solid {
          translation 0 0 0.01
          children [
            Shape {
              appearance PBRAppearance {
              }
              geometry Cylinder {
                height 0.02
                radius 0.002
              }
            }
          ]
        }
      ]
    }
    DEF BODY Shape {
      appearance PBRAppearance {
        baseColor 0.917647 0.917647 0.917647
        baseColorMap ImageTexture {
          url [
            "textures/4x4_1000-0 (Custom).png"
          ]
        }
        roughness 1
        metalness 0
      }
      geometry Box {
        size 0.5 0.5 0.05
      }
    }
    DEF WHEEL1 HingeJoint {
      jointParameters HingeJointParameters {
        position 9.347513871526907e-09
        axis 0 1 0
        anchor 0.18 0.26 0
      }
      device [
        RotationalMotor {
          name "wheel1"
        }
      ]
      endPoint Solid {
        translation 0.18 0.26 0
        rotation 1 4.673739846631692e-09 -4.673759173141099e-09 1.5707999999999882
        children [
          DEF WHEEL Shape {
            appearance PBRAppearance {
              baseColor 0.305882 0.898039 0.25098
              roughness 1
              metalness 0
            }
            geometry Cylinder {
              height 0.02
              radius 0.04
              subdivision 24
            }
          }
        ]
        boundingObject USE WHEEL
        physics Physics {
        }
      }
    }
    DEF WHEEL2 HingeJoint {
      jointParameters HingeJointParameters {
        position 1.0049746295156312e-08
        axis 0 1 0
        anchor 0.18 -0.26 0
      }
      device [
        RotationalMotor {
          name "wheel2"
        }
      ]
      endPoint Solid {
        translation 0.18 -0.26 0
        rotation 1 5.024852609853765e-09 -5.0248726372990465e-09 1.570799999999983
        children [
          USE WHEEL
        ]
        name "solid(1)"
        boundingObject USE WHEEL
        physics Physics {
        }
      }
    }
    DEF WHEEL3 HingeJoint {
      jointParameters HingeJointParameters {
        position -1.183077672291902e-08
        axis 0 1 0
        anchor -0.18 0.26 0
      }
      device [
        RotationalMotor {
          name "wheel3"
        }
      ]
      endPoint Solid {
        translation -0.18 0.26 0
        rotation 1 -5.915368085397658e-09 5.915389028747579e-09 1.5707999999999829
        children [
          USE WHEEL
        ]
        name "solid(2)"
        boundingObject USE WHEEL
        physics Physics {
        }
      }
    }
    DEF WHEEL4 HingeJoint {
      jointParameters HingeJointParameters {
        position -1.1689693413617427e-08
        axis 0 1 0
        anchor -0.18 -0.26 0
      }
      device [
        RotationalMotor {
          name "wheel4"
        }
      ]
      endPoint Solid {
        translation -0.18 -0.26 0
        rotation 1 -5.84482457023939e-09 5.844847256340065e-09 1.5707999999999889
        children [
          USE WHEEL
        ]
        name "solid(3)"
        boundingObject USE WHEEL
        physics Physics {
        }
      }
    }
    DEF DS_RIGHT DistanceSensor {
      translation 0.16 -0.03 0
      rotation 0 0 1 -0.3
      children [
        Shape {
          appearance PBRAppearance {
            baseColor 0.184314 0.596078 0.847059
            roughness 1
            metalness 0
          }
          geometry Box {
            size 0.01 0.01 0.01
          }
        }
      ]
      name "ds_right"
    }
    DEF DS_LEFT DistanceSensor {
      translation 0.16 0.03 0
      rotation 0 0 1 0.3
      children [
        Shape {
          appearance PBRAppearance {
            baseColor 0.184314 0.596078 0.847059
            roughness 1
            metalness 0
          }
          geometry Box {
            size 0.01 0.01 0.01
          }
        }
      ]
      name "ds_left"
    }
  ]
  boundingObject USE BODY
  physics Physics {
    density -1
    mass 1
  }
  controller "ground_controller"
}
Mavic2Pro {
  translation -0.0036604558154140618 -0.00388180705142184 0.13061341999800044
  controller "mavic_controller"
  customData "0"
  supervisor TRUE
  cameraSlot [
    Camera {
      width 400
      height 240
      near 0.2
    }
  ]
}
