#VRML_SIM R2023b utf8

EXTERNPROTO "https://raw.githubusercontent.com/cyberbotics/webots/R2023b/projects/objects/backgrounds/protos/TexturedBackground.proto"
EXTERNPROTO "https://raw.githubusercontent.com/cyberbotics/webots/R2023b/projects/objects/backgrounds/protos/TexturedBackgroundLight.proto"
EXTERNPROTO "https://raw.githubusercontent.com/cyberbotics/webots/R2023b/projects/objects/floors/protos/Floor.proto"
EXTERNPROTO "https://raw.githubusercontent.com/cyberbotics/webots/R2023b/projects/robots/dji/mavic/protos/Mavic2Pro.proto"
EXTERNPROTO "https://raw.githubusercontent.com/cyberbotics/webots/R2023b/projects/appearances/protos/SandyGround.proto"

WorldInfo {
  basicTimeStep 16
  defaultDamping Damping {
    linear 0.5
    angular 0.3
  }
}
Viewpoint {
  orientation -0.22800680889002 0.09183714719809945 0.9693187471076293 2.3971559146743573
  position 1.8616435938713776 -1.558138425622659 1.4186047465234202
  follow "Mavic 2 PRO"
  followType "None"
}
TexturedBackground {
}
TexturedBackgroundLight {
}
Floor {
  size 15 15
  appearance SandyGround {
  }
}
Robot {
  translation 0 0 0.0520842
  rotation 0 0 1 1.5788812805631136
  children [
    GPS {
      translation 0 0 0.005
      children [
        Solid {
          translation 0 0 0.01
          children [
            Shape {
              appearance PBRAppearance {
              }
              geometry Cylinder {
                height 0.02
                radius 0.002
              }
            }
          ]
        }
      ]
      name "gps_ground"
    }
    DEF BODY Shape {
      appearance PBRAppearance {
        baseColor 0.917647 0.917647 0.917647
        baseColorMap ImageTexture {
          url [
            "textures/4x4_1000-0 (Custom).png"
          ]
        }
        roughness 1
        metalness 0
      }
      geometry Box {
        size 0.5 0.5 0.05
      }
    }
    DEF WHEEL1 HingeJoint {
      jointParameters HingeJointParameters {
        position -0.1434581245247754
        axis 0 1 0
        anchor 0.18 0.26 0
      }
      device [
        RotationalMotor {
          name "wheel1"
        }
      ]
      endPoint Solid {
        translation 0.18 0.26 0
        rotation 0.9948769011186247 -0.07148396351848554 0.0714842260942244 1.5759362443140381
        children [
          DEF WHEEL Shape {
            appearance PBRAppearance {
              baseColor 0.305882 0.898039 0.25098
              roughness 1
              metalness 0
            }
            geometry Cylinder {
              height 0.02
              radius 0.04
              subdivision 24
            }
          }
        ]
        boundingObject USE WHEEL
        physics Physics {
        }
      }
    }
    DEF WHEEL2 HingeJoint {
      jointParameters HingeJointParameters {
        position -0.1826447995228828
        axis 0 1 0
        anchor 0.18 -0.26 0
      }
      device [
        RotationalMotor {
          name "wheel2"
        }
      ]
      endPoint Solid {
        translation 0.18 -0.26 0
        rotation 0.9917177048329069 -0.09081831678627016 0.09081865038118442 1.5791166879339338
        children [
          USE WHEEL
        ]
        name "solid(1)"
        boundingObject USE WHEEL
        physics Physics {
        }
      }
    }
    DEF WHEEL3 HingeJoint {
      jointParameters HingeJointParameters {
        position -3.762933256196769e-08
        axis 0 1 0
        anchor -0.18 0.26 0
      }
      device [
        RotationalMotor {
          name "wheel3"
        }
      ]
      endPoint Solid {
        translation -0.18 0.26 0
        rotation 0.9999999999999996 -1.881459862331575e-08 1.8814666948271903e-08 1.5707999999999829
        children [
          USE WHEEL
        ]
        name "solid(2)"
        boundingObject USE WHEEL
        physics Physics {
        }
      }
    }
    DEF WHEEL4 HingeJoint {
      jointParameters HingeJointParameters {
        position -3.701531388630144e-08
        axis 0 1 0
        anchor -0.18 -0.26 0
      }
      device [
        RotationalMotor {
          name "wheel4"
        }
      ]
      endPoint Solid {
        translation -0.18 -0.26 0
        rotation 0.9999999999999996 -1.850758829356777e-08 1.8507657492682063e-08 1.570799999999989
        children [
          USE WHEEL
        ]
        name "solid(3)"
        boundingObject USE WHEEL
        physics Physics {
        }
      }
    }
    DEF DS_RIGHT DistanceSensor {
      translation 0.16 -0.03 0
      rotation 0 0 1 -0.3
      children [
        Shape {
          appearance PBRAppearance {
            baseColor 0.184314 0.596078 0.847059
            roughness 1
            metalness 0
          }
          geometry Box {
            size 0.01 0.01 0.01
          }
        }
      ]
      name "ds_right"
    }
    DEF DS_LEFT DistanceSensor {
      translation 0.16 0.03 0
      rotation 0 0 1 0.3
      children [
        Shape {
          appearance PBRAppearance {
            baseColor 0.184314 0.596078 0.847059
            roughness 1
            metalness 0
          }
          geometry Box {
            size 0.01 0.01 0.01
          }
        }
      ]
      name "ds_left"
    }
  ]
  boundingObject USE BODY
  physics Physics {
    density -1
    mass 1
  }
  controller "ground_controller"
}
Mavic2Pro {
  translation 0 0 0.182536
  rotation 0 0 1 1.57888
  controller "mavic_controller"
  customData "0"
  bodySlot [
    GPS {
      name "gpss"
    }
  ]
  cameraSlot [
    Camera {
      width 400
      height 240
      near 0.2
    }
  ]
}
